Workbook

Sheet Sheet1
A1: new_id | B1: latitude | C1: longitude | D1: 都道府県
A2: C01 | B2: 35.003502 | C2: 135.74716 | D2: 京都府
A3: C01 | B3: 35.003555 | C3: 135.74722 | D3: 京都府
A4: C01 | B4: 35.003822 | C4: 135.74808 | D4: 京都府
A5: C01 | B5: 35.003799 | C5: 135.74811 | D5: 京都府
A6: C01 | B6: 35.695362 | C6: 139.75865 | D6: 東京都
A7: C01 | B7: 35.695534 | C7: 139.76298 | D7: 東京都
A8: C01 | B8: 25.413939 | C8: 123.11461 | D8: 沖縄県
A9: C01 | B9: 25.415457 | C9: 123.1243 | D9: 沖縄県
A10: C01 | B10: 24.331825 | C10: 124.1496 | D10: 沖縄県
A11: C01 | B11: 24.337093 | C11: 124.15535 | D11: 沖縄県
A12: C01 | B12: 36.350647 | C12: 138.62685 | D12: 長野県
A13: C01 | B13: 36.342243 | C13: 138.63472 | D13: 長野県
... A3092: C32 | B3092: 35.681372 | C3092: 139.91952 | D3092: 東京都

Sheet Sheet2
A1: {
A2: "counties": [
A3: {
A4: "id": "county_1",
A5: "title": "愛知",
A6: "path": "M6284.96 5306.1L6280.85 5299.41L6292.94 5265.58L6272.15 5238.82L6274.81 5210.92L6285.93 5184.73L6279.89 5178.62L6258.37 5185.5L6230.8 5178.81L6207.35 5148.8L6199.61 5125.67L6204.93 5083.81L6245.79 5027.05L6276.74 5029.91L6316.88 5020.36L6352.66 4998.76L6352.18 5009.65L6380.71 5026.28L6379.99 5038.71L6392.08 5042.72L6389.9 5051.89L6396.43 5058.01L6404.17 5060.88L6411.42 5056.86L6434.15 5064.32L6446.72 5077.89L6467.27 5074.64L6489.52 5060.69L6504.75 5060.5L6522.88 5069.48L6521.19 5074.07L6541.5 5075.02L6541.02 5080.95L6564.96 5090.5L6606.54 5063.75L6625.89 5062.22L6618.15 5078.08L6633.62 5093.56L6633.38 5103.31L6663.85 5098.34L6684.4 5087.83L6722.12 5093.56L6727.44 5101.02L6747.75 5095.86L6740.25 5114.59L6752.83 5124.14L6738.8 5135.04L6740.74 5144.02L6729.61 5148.61L6694.31 5186.83L6693.59 5207.09L6662.64 5243.98L6596.15 5273.23L6585.75 5296.73L6589.62 5341.08L6507.17 5356.18L6424.23 5379.69L6375.15 5384.85L6368.86 5380.83L6388.21 5348.15L6400.05 5349.11L6406.1 5360L6463.16 5340.5L6483.96 5330.37L6481.54 5321.96L6492.42 5315.08L6504.02 5317.95L6509.34 5314.32L6514.42 5292.53L6500.64 5279.15L6459.78 5273.23L6447.2 5282.02L6441.4 5299.79L6421.82 5288.9L6370.31 5293.68L6335.98 5267.49L6343.48 5246.85L6332.84 5243.22L6322.68 5254.49L6316.15 5296.93L6340.82 5314.7L6344.44 5331.52L6303.58 5320.05L6284.96 5306.1Z",
A7: "center": [
A8: 6476.219999999999,
A9: 5191.805
A10: ]
A11: },
A12: {
A13: "id": "county_2",
A14: "title": "秋田",
A15: "path": "M7814.29 2965.3L7797.6 2912.74L7763.99 2881.78L7776.32 2866.3L7794.22 2870.69L7808.72 2887.7L7813.32 2865.91L7807.03 2858.08L7816.7 2846.42L7821.3 2819.66L7813.08 2792.71L7787.2 2784.3L7776.32 2792.52L7763.27 2808L7748.52 2847.38L7761.58 2855.4L7759.64 2879.49L7741.51 2873.94L7719.99 2876.81L7715.39 2881.59L7719.5 2897.83L7668.73 2896.11L7645.52 2860.95L7640.2 2836.1L7643.58 2822.15L7690.25 2847.38L7706.45 2843.36L7742.23 2815.46L7763.27 2785.45L7782.61 2739.77L7797.12 2682.43L7797.84 2650.51L7756.26 2615.91L7768.59 2613.81L7795.91 2620.5L7802.2 2603.87L7820.81 2597.18L7833.87 2603.3L7838.95 2612.66L7874.73 2610.18L7894.32 2615.53L7926.96 2608.27L7947.75 2611.71L7959.84 2592.6L7991.52 2590.49L7998.05 2606.55H8017.39L8045.19 2629.29L8069.37 2613.24L8099.6 2629.29L8118.7 2617.25L8137.07 2616.3L8154.48 2604.45L8171.65 2606.36L8177.45 2585.72L8207.19 2576.35L8203.33 2621.27L8254.83 2616.87L8261.6 2652.04L8251.68 2657.2L8239.59 2680.52L8242.98 2705.55L8233.31 2716.45L8218.56 2720.65L8198.97 2741.87L8208.64 2751.24L8205.02 2781.05L8192.44 2789.84L8191.24 2841.07L8206.23 2888.85L8192.69 2892.29L8180.84 2883.12L8161.01 2891.72L8162.7 2911.98L8189.78 2924.59L8169.96 2952.69L8160.53 2955.36L8176.49 2977.73L8179.63 2998.37L8167.3 3021.11L8160.77 3020.54L8146.02 3036.98L8135.87 3039.08L8140.94 3052.84L8130.55 3078.45L8111.69 3094.7L8112.9 3110.18L8102.02 3112.48L8100.81 3124.9L8110.24 3126.62L8124.74 3150.51L8121.12 3168.1L8133.93 3182.43L8161.01 3197.15L8153.03 3217.41L8173.59 3225.82L8159.08 3231.55L8147.71 3247.41L8154.24 3251.62L8147.47 3270.16L8170.93 3277.42L8174.31 3285.07L8155.21 3311.25L8157.14 3333.23L8139.98 3336.48L8100.32 3366.49L8057.77 3373.37L8051.24 3369.93L8045.44 3361.33L8008.68 3351.2L7994.66 3316.8L7969.03 3315.27L7960.57 3300.55L7934.45 3305.71L7859.98 3287.74L7840.88 3274.36L7823.72 3270.92L7818.88 3248.56L7795.18 3253.15L7786.24 3261.94L7725.55 3254.1L7741.99 3226.01L7736.43 3208.23L7745.86 3193.32L7744.89 3183.19L7754.32 3171.54L7771.25 3169.43L7793.97 3123.75L7813.32 3043.67L7814.29 2965.3Z",
A16: "center": [
A17: 7950.9,
A18: 2974.86
A19: ]
A20: },
A21: {
A22: "id": "county_3",
A23: "title": "青森",
A24: "path": "M8325.18 2396.49L8347.42 2380.63L8361.44 2360.56L8375.23 2325.2L8380.79 2278.37L8395.05 2256.59L8377.65 2217.21L8356.85 2197.33L8337.75 2195.81L8317.2 2226.58L8289.88 2242.06L8253.12 2234.03L8236.92 2246.46L8193.16 2252.95L8172.61 2269.58L8150.12 2260.6L8166.8 2172.87L8176.96 2160.25L8184.45 2125.09L8219.03 2086.29L8213.71 2070.61L8220.97 2060.1L8262.55 2090.11L8294.47 2092.21L8315.99 2101.77L8353.95 2139.42L8389.25 2155.67L8410.77 2157.77L8434.95 2150.7L8484.27 2118.78L8448.25 2249.7L8445.83 2346.99L8459.13 2453.07L8492.25 2545.96L8520.78 2566.79L8536.98 2559.34L8542.55 2569.85L8588.73 2605.97L8577.36 2616.3L8543.75 2628.15L8541.09 2644.01L8519.58 2657.2L8489.59 2642.48L8473.15 2644.2L8431.56 2665.23L8415.12 2644.58L8367.73 2673.06L8330.98 2680.33L8313.09 2689.88L8312.12 2703.64L8301 2704.03L8276.82 2718.93L8254.09 2718.74L8242.97 2705.75L8239.58 2680.71L8251.67 2657.39L8261.59 2652.23L8254.82 2617.06L8203.31 2621.46L8207.18 2576.54L8177.44 2585.91L8171.64 2606.55L8154.47 2604.64L8137.06 2616.49L8118.69 2617.44L8099.59 2629.48L8069.36 2613.43L8045.18 2629.48L8017.38 2606.74H7998.03L7991.51 2590.68L7959.83 2592.79L7947.74 2611.9L7926.95 2608.46L7894.31 2615.72L7874.72 2610.37L7838.94 2612.86L7833.86 2603.49L7820.8 2597.37L7802.18 2604.06L7795.9 2620.69L7768.58 2614L7756.24 2616.1L7762.53 2582.08L7757.94 2554.56L7747.06 2538.12L7723.84 2539.08L7720.22 2523.41L7763.26 2496.26L7787.92 2461.86L7803.64 2453.45L7818.38 2448.67L7848.13 2461.86L7882.7 2441.41L7902.29 2439.5L7912.44 2427.84L7937.1 2358.84L7938.8 2286.21L7922.11 2271.88L7905.19 2270.35L7909.3 2262.89L7930.58 2267.29L7939.76 2259.07L7949.43 2202.69L7975.79 2215.87L7991.99 2234.8L8007.46 2241.68L8023.66 2238.05L8047.84 2218.74L8074.2 2226L8089.92 2239.77L8087.26 2283.15L8096.69 2331.32L8114.34 2394.01L8136.82 2416.75L8168.98 2414.65L8197.75 2390.19L8203.07 2379.48L8197.75 2355.78L8205.73 2328.07L8241.76 2338.39L8258.2 2356.74L8253.85 2367.25L8271.5 2367.06L8293.74 2375.66L8306.56 2392.48L8325.18 2396.49Z",
A25: "center": [
A26: 8154.475,
A27: 2389.515
A28: ]
A29: },
A30: {
A31: "id": "county_4",
A32: "title": "千葉",
A33: "path": "M7709.34 5023.99L7712.73 5019.98L7735.94 5028L7745.37 5019.02L7738.11 5005.26L7740.29 4994.17L7772.93 4986.91L7770.03 4977.16L7776.8 4974.68L7782.6 4981.94L7819.11 4940.66L7832.89 4949.26L7838.46 4942.57L7825.4 4917.91L7807.02 4902.05L7777.77 4879.3L7761.08 4884.84L7752.62 4870.32L7726.51 4827.12L7734.73 4822.15L7740.05 4796.73L7699.43 4735.19L7698.22 4715.31L7681.05 4688.36L7691.21 4688.93L7699.18 4704.99L7738.6 4743.41L7756 4747.99L7760.84 4761.56L7785.99 4774.94L7845.47 4791.38L7859.49 4805.14L7884.15 4797.31L7904.95 4799.41L7919.21 4791.76L7938.56 4796.16L7959.35 4780.49L8007.95 4770.55L8034.06 4780.49L8056.07 4779.72L8083.39 4798.26L8113.13 4803.23L8139.97 4832.47L8200.42 4861.91L8197.76 4874.33L8179.38 4864.58L8143.11 4874.14L8123.77 4869.94L8105.63 4873.57L8039.87 4913.13L8006.26 4943.14L7979.18 4984.42L7972.17 5028.77L7983.53 5052.28L7968.78 5106.75L7952.58 5109.43L7941.22 5128.92L7934.45 5130.83L7882.46 5142.68L7876.9 5134.27L7845.95 5137.9L7826.37 5158.93L7778.73 5184.92L7766.4 5208.05L7768.82 5219.13L7757.94 5230.79L7732.79 5239.01L7704.5 5235L7699.91 5221.24L7668.24 5208.43L7668.96 5202.89L7688.3 5204.99L7718.53 5194.29L7699.67 5162.56L7710.79 5153L7702.09 5146.12L7709.1 5132.74L7699.18 5121.85L7699.43 5105.98L7721.67 5092.41L7723.61 5082.48L7712.97 5068.14L7714.42 5060.69L7696.28 5051.89L7709.34 5023.99Z",
A34: "center": [
A35: 7934.33,
A36: 4963.685
A37: ]
A38: },
A39: {
A40: "id": "county_5",
...

Sheet Sheet3
A1: county_id | B1: title | C1: C01 | D1: C02 | E1: C03 | F1: C04 | G1: C05 | H1: C06 | I1: C07 | J1: C08 | K1: C09 | L1: C10 | M1: C11 | N1: C12 | O1: C13 | P1: C14 | Q1: C15 | R1: C16 | S1: C17 | T1: C18 | U1: C19 | V1: C20 | W1: C21 | X1: C22 | Y1: C23 | Z1: C24 | AA1: C25 | AB1: C26 | AC1: C27 | AD1: C28 | AE1: C29 | AF1: C30 | AG1: C31 | AH1: C32
A2: county_1 | B2: 愛知 | C2: {=COUNTIFS(Sheet1!$A:$A,C$1,Sheet1!$D:$D,_xlfn.SWITCH($B2,"廣島","広島","鹿兒島","鹿児島","沖繩","沖縄","崎玉","埼玉","靜岡","静岡","櫪木","栃木","德島","徳島",$B2)&"*")} -> 0 | D2: {=COUNTIFS(Sheet1!$A:$A,D$1,Sheet1!$D:$D,_xlfn.SWITCH($B2,"廣島","広島","鹿兒島","鹿児島","沖繩","沖縄","崎玉","埼玉","靜岡","静岡","櫪木","栃木","德島","徳島",$B2)&"*")} -> 0 | E2: {=COUNTIFS(Sheet1!$A:$A,E$1,Sheet1!$D:$D,_xlfn.SWITCH($B2,"廣島","広島","鹿兒島","鹿児島","沖繩","沖縄","崎玉","埼玉","靜岡","静岡","櫪木","栃木","德島","徳島",$B2)&"*")} -> 0 | F2: {=COUNTIFS(Sheet1!$A:$A,F$1,Sheet1!$D:$D,_xlfn.SWITCH($B2,"廣島","広島","鹿兒島","鹿児島","沖繩","沖縄","崎玉","埼玉","靜岡","静岡","櫪木","栃木","德島","徳島",$B2)&"*")} -> 0 | G2: {=COUNTIFS(Sheet1!$A:$A,G$1,Sheet1!$D:$D,_xlfn.SWITCH($B2,"廣島","広島","鹿兒島","鹿児島","沖繩","沖縄","崎玉","埼玉","靜岡","静岡","櫪木","栃木","德島","徳島",$B2)&"*")} -> 4 | H2: {=COUNTIFS(Sheet1!$A:$A,H$1,Sheet1!$D:$D,_xlfn.SWITCH($B2,"廣島","広島","鹿兒島","鹿児島","沖繩","沖縄","崎玉","埼玉","靜岡","静岡","櫪木","栃木","德島","徳島",$B2)&"*")} -> 0 | I2: {=COUNTIFS(Sheet1!$A:$A,I$1,Sheet1!$D:$D,_xlfn.SWITCH($B2,"廣島","広島","鹿兒島","鹿児島","沖繩","沖縄","崎玉","埼玉","靜岡","静岡","櫪木","栃木","德島","徳島",$B2)&"*")} -> 2 | J2: {=COUNTIFS(Sheet1!$A:$A,J$1,Sheet1!$D:$D,_xlfn.SWITCH($B2,"廣島","広島","鹿兒島","鹿児島","沖繩","沖縄","崎玉","埼玉","靜岡","静岡","櫪木","栃木","德島","徳島",$B2)&"*")} -> 0 | ... AH2: {=COUNTIFS(Sheet1!$A:$A,AH$1,Sheet1!$D:$D,_xlfn.SWITCH($B2,"廣島","広島","鹿兒島","鹿児島","沖繩","沖縄","崎玉","埼玉","靜岡","静岡","櫪木","栃木","德島","徳島",$B2)&"*")} -> 0
A3: county_2 | B3: 秋田 | C3: {=COUNTIFS(Sheet1!$A:$A,C$1,Sheet1!$D:$D,_xlfn.SWITCH($B3,"廣島","広島","鹿兒島","鹿児島","沖繩","沖縄","崎玉","埼玉","靜岡","静岡","櫪木","栃木","德島","徳島",$B3)&"*")} -> 6 | D3: {=COUNTIFS(Sheet1!$A:$A,D$1,Sheet1!$D:$D,_xlfn.SWITCH($B3,"廣島","広島","鹿兒島","鹿児島","沖繩","沖縄","崎玉","埼玉","靜岡","静岡","櫪木","栃木","德島","徳島",$B3)&"*")} -> 6 | E3: {=COUNTIFS(Sheet1!$A:$A,E$1,Sheet1!$D:$D,_xlfn.SWITCH($B3,"廣島","広島","鹿兒島","鹿児島","沖繩","沖縄","崎玉","埼玉","靜岡","静岡","櫪木","栃木","德島","徳島",$B3)&"*")} -> 0 | F3: {=COUNTIFS(Sheet1!$A:$A,F$1,Sheet1!$D:$D,_xlfn.SWITCH($B3,"廣島","広島","鹿兒島","鹿児島","沖繩","沖縄","崎玉","埼玉","靜岡","静岡","櫪木","栃木","德島","徳島",$B3)&"*")} -> 0 | G3: {=COUNTIFS(Sheet1!$A:$A,G$1,Sheet1!$D:$D,_xlfn.SWITCH($B3,"廣島","広島","鹿兒島","鹿児島","沖繩","沖縄","崎玉","埼玉","靜岡","静岡","櫪木","栃木","德島","徳島",$B3)&"*")} -> 0 | H3: {=COUNTIFS(Sheet1!$A:$A,H$1,Sheet1!$D:$D,_xlfn.SWITCH($B3,"廣島","広島","鹿兒島","鹿児島","沖繩","沖縄","崎玉","埼玉","靜岡","静岡","櫪木","栃木","德島","徳島",$B3)&"*")} -> 0 | I3: {=COUNTIFS(Sheet1!$A:$A,I$1,Sheet1!$D:$D,_xlfn.SWITCH($B3,"廣島","広島","鹿兒島","鹿児島","沖繩","沖縄","崎玉","埼玉","靜岡","静岡","櫪木","栃木","德島","徳島",$B3)&"*")} -> 0 | J3: {=COUNTIFS(Sheet1!$A:$A,J$1,Sheet1!$D:$D,_xlfn.SWITCH($B3,"廣島","広島","鹿兒島","鹿児島","沖繩","沖縄","崎玉","埼玉","靜岡","静岡","櫪木","栃木","德島","徳島",$B3)&"*")} -> 0 | ... AH3: {=COUNTIFS(Sheet1!$A:$A,AH$1,Sheet1!$D:$D,_xlfn.SWITCH($B3,"廣島","広島","鹿兒島","鹿児島","沖繩","沖縄","崎玉","埼玉","靜岡","静岡","櫪木","栃木","德島","徳島",$B3)&"*")} -> 0
A4: county_3 | B4: 青森 | C4: {=COUNTIFS(Sheet1!$A:$A,C$1,Sheet1!$D:$D,_xlfn.SWITCH($B4,"廣島","広島","鹿兒島","鹿児島","沖繩","沖縄","崎玉","埼玉","靜岡","静岡","櫪木","栃木","德島","徳島",$B4)&"*")} -> 0 | D4: {=COUNTIFS(Sheet1!$A:$A,D$1,Sheet1!$D:$D,_xlfn.SWITCH($B4,"廣島","広島","鹿兒島","鹿児島","沖繩","沖縄","崎玉","埼玉","靜岡","静岡","櫪木","栃木","德島","徳島",$B4)&"*")} -> 0 | E4: {=COUNTIFS(Sheet1!$A:$A,E$1,Sheet1!$D:$D,_xlfn.SWITCH($B4,"廣島","広島","鹿兒島","鹿児島","沖繩","沖縄","崎玉","埼玉","靜岡","静岡","櫪木","栃木","德島","徳島",$B4)&"*")} -> 0 | F4: {=COUNTIFS(Sheet1!$A:$A,F$1,Sheet1!$D:$D,_xlfn.SWITCH($B4,"廣島","広島","鹿兒島","鹿児島","沖繩","沖縄","崎玉","埼玉","靜岡","静岡","櫪木","栃木","德島","徳島",$B4)&"*")} -> 2 | G4: {=COUNTIFS(Sheet1!$A:$A,G$1,Sheet1!$D:$D,_xlfn.SWITCH($B4,"廣島","広島","鹿兒島","鹿児島","沖繩","沖縄","崎玉","埼玉","靜岡","静岡","櫪木","栃木","德島","徳島",$B4)&"*")} -> 0 | H4: {=COUNTIFS(Sheet1!$A:$A,H$1,Sheet1!$D:$D,_xlfn.SWITCH($B4,"廣島","広島","鹿兒島","鹿児島","沖繩","沖縄","崎玉","埼玉","靜岡","静岡","櫪木","栃木","德島","徳島",$B4)&"*")} -> 2 | I4: {=COUNTIFS(Sheet1!$A:$A,I$1,Sheet1!$D:$D,_xlfn.SWITCH($B4,"廣島","広島","鹿兒島","鹿児島","沖繩","沖縄","崎玉","埼玉","靜岡","静岡","櫪木","栃木","德島","徳島",$B4)&"*")} -> 0 | J4: {=COUNTIFS(Sheet1!$A:$A,J$1,Sheet1!$D:$D,_xlfn.SWITCH($B4,"廣島","広島","鹿兒島","鹿児島","沖繩","沖縄","崎玉","埼玉","靜岡","静岡","櫪木","栃木","德島","徳島",$B4)&"*")} -> 0 | ... AH4: {=COUNTIFS(Sheet1!$A:$A,AH$1,Sheet1!$D:$D,_xlfn.SWITCH($B4,"廣島","広島","鹿兒島","鹿児島","沖繩","沖縄","崎玉","埼玉","靜岡","静岡","櫪木","栃木","德島","徳島",$B4)&"*")} -> 0
A5: county_4 | B5: 千葉 | C5: {=COUNTIFS(Sheet1!$A:$A,C$1,Sheet1!$D:$D,_xlfn.SWITCH($B5,"廣島","広島","鹿兒島","鹿児島","沖繩","沖縄","崎玉","埼玉","靜岡","静岡","櫪木","栃木","德島","徳島",$B5)&"*")} -> 2 | D5: {=COUNTIFS(Sheet1!$A:$A,D$1,Sheet1!$D:$D,_xlfn.SWITCH($B5,"廣島","広島","鹿兒島","鹿児島","沖繩","沖縄","崎玉","埼玉","靜岡","静岡","櫪木","栃木","德島","徳島",$B5)&"*")} -> 0 | E5: {=COUNTIFS(Sheet1!$A:$A,E$1,Sheet1!$D:$D,_xlfn.SWITCH($B5,"廣島","広島","鹿兒島","鹿児島","沖繩","沖縄","崎玉","埼玉","靜岡","静岡","櫪木","栃木","德島","徳島",$B5)&"*")} -> 6 | F5: {=COUNTIFS(Sheet1!$A:$A,F$1,Sheet1!$D:$D,_xlfn.SWITCH($B5,"廣島","広島","鹿兒島","鹿児島","沖繩","沖縄","崎玉","埼玉","靜岡","静岡","櫪木","栃木","德島","徳島",$B5)&"*")} -> 0 | G5: {=COUNTIFS(Sheet1!$A:$A,G$1,Sheet1!$D:$D,_xlfn.SWITCH($B5,"廣島","広島","鹿兒島","鹿児島","沖繩","沖縄","崎玉","埼玉","靜岡","静岡","櫪木","栃木","德島","徳島",$B5)&"*")} -> 7 | H5: {=COUNTIFS(Sheet1!$A:$A,H$1,Sheet1!$D:$D,_xlfn.SWITCH($B5,"廣島","広島","鹿兒島","鹿児島","沖繩","沖縄","崎玉","埼玉","靜岡","静岡","櫪木","栃木","德島","徳島",$B5)&"*")} -> 0 | I5: {=COUNTIFS(Sheet1!$A:$A,I$1,Sheet1!$D:$D,_xlfn.SWITCH($B5,"廣島","広島","鹿兒島","鹿児島","沖繩","沖縄","崎玉","埼玉","靜岡","静岡","櫪木","栃木","德島","徳島",$B5)&"*")} -> 0 | J5: {=COUNTIFS(Sheet1!$A:$A,J$1,Sheet1!$D:$D,_xlfn.SWITCH($B5,"廣島","広島","鹿兒島","鹿児島","沖繩","沖縄","崎玉","埼玉","靜岡","静岡","櫪木","栃木","德島","徳島",$B5)&"*")} -> 0 | ... AH5: {=COUNTIFS(Sheet1!$A:$A,AH$1,Sheet1!$D:$D,_xlfn.SWITCH($B5,"廣島","広島","鹿兒島","鹿児島","沖繩","沖縄","崎玉","埼玉","靜岡","静岡","櫪木","栃木","德島","徳島",$B5)&"*")} -> 0
A6: county_5 | B6: 愛媛 | C6: {=COUNTIFS(Sheet1!$A:$A,C$1,Sheet1!$D:$D,_xlfn.SWITCH($B6,"廣島","広島","鹿兒島","鹿児島","沖繩","沖縄","崎玉","埼玉","靜岡","静岡","櫪木","栃木","德島","徳島",$B6)&"*")} -> 0 | D6: {=COUNTIFS(Sheet1!$A:$A,D$1,Sheet1!$D:$D,_xlfn.SWITCH($B6,"廣島","広島","鹿兒島","鹿児島","沖繩","沖縄","崎玉","埼玉","靜岡","静岡","櫪木","栃木","德島","徳島",$B6)&"*")} -> 0 | E6: {=COUNTIFS(Sheet1!$A:$A,E$1,Sheet1!$D:$D,_xlfn.SWITCH($B6,"廣島","広島","鹿兒島","鹿児島","沖繩","沖縄","崎玉","埼玉","靜岡","静岡","櫪木","栃木","德島","徳島",$B6)&"*")} -> 0 | F6: {=COUNTIFS(Sheet1!$A:$A,F$1,Sheet1!$D:$D,_xlfn.SWITCH($B6,"廣島","広島","鹿兒島","鹿児島","沖繩","沖縄","崎玉","埼玉","靜岡","静岡","櫪木","栃木","德島","徳島",$B6)&"*")} -> 0 | G6: {=COUNTIFS(Sheet1!$A:$A,G$1,Sheet1!$D:$D,_xlfn.SWITCH($B6,"廣島","広島","鹿兒島","鹿児島","沖繩","沖縄","崎玉","埼玉","靜岡","静岡","櫪木","栃木","德島","徳島",$B6)&"*")} -> 0 | H6: {=COUNTIFS(Sheet1!$A:$A,H$1,Sheet1!$D:$D,_xlfn.SWITCH($B6,"廣島","広島","鹿兒島","鹿児島","沖繩","沖縄","崎玉","埼玉","靜岡","静岡","櫪木","栃木","德島","徳島",$B6)&"*")} -> 0 | I6: {=COUNTIFS(Sheet1!$A:$A,I$1,Sheet1!$D:$D,_xlfn.SWITCH($B6,"廣島","広島","鹿兒島","鹿児島","沖繩","沖縄","崎玉","埼玉","靜岡","静岡","櫪木","栃木","德島","徳島",$B6)&"*")} -> 0 | J6: {=COUNTIFS(Sheet1!$A:$A,J$1,Sheet1!$D:$D,_xlfn.SWITCH($B6,"廣島","広島","鹿兒島","鹿児島","沖繩","沖縄","崎玉","埼玉","靜岡","静岡","櫪木","栃木","德島","徳島",$B6)&"*")} -> 1 | ... AH6: {=COUNTIFS(Sheet1!$A:$A,AH$1,Sheet1!$D:$D,_xlfn.SWITCH($B6,"廣島","広島","鹿兒島","鹿児島","沖繩","沖縄","崎玉","埼玉","靜岡","静岡","櫪木","栃木","德島","徳島",$B6)&"*")} -> 0
A7: county_6 | B7: 福井 | C7: {=COUNTIFS(Sheet1!$A:$A,C$1,Sheet1!$D:$D,_xlfn.SWITCH($B7,"廣島","広島","鹿兒島","鹿児島","沖繩","沖縄","崎玉","埼玉","靜岡","静岡","櫪木","栃木","德島","徳島",$B7)&"*")} -> 0 | D7: {=COUNTIFS(Sheet1!$A:$A,D$1,Sheet1!$D:$D,_xlfn.SWITCH($B7,"廣島","広島","鹿兒島","鹿児島","沖繩","沖縄","崎玉","埼玉","靜岡","静岡","櫪木","栃木","德島","徳島",$B7)&"*")} -> 0 | E7: {=COUNTIFS(Sheet1!$A:$A,E$1,Sheet1!$D:$D,_xlfn.SWITCH($B7,"廣島","広島","鹿兒島","鹿児島","沖繩","沖縄","崎玉","埼玉","靜岡","静岡","櫪木","栃木","德島","徳島",$B7)&"*")} -> 0 | F7: {=COUNTIFS(Sheet1!$A:$A,F$1,Sheet1!$D:$D,_xlfn.SWITCH($B7,"廣島","広島","鹿兒島","鹿児島","沖繩","沖縄","崎玉","埼玉","靜岡","静岡","櫪木","栃木","德島","徳島",$B7)&"*")} -> 0 | G7: {=COUNTIFS(Sheet1!$A:$A,G$1,Sheet1!$D:$D,_xlfn.SWITCH($B7,"廣島","広島","鹿兒島","鹿児島","沖繩","沖縄","崎玉","埼玉","靜岡","静岡","櫪木","栃木","德島","徳島",$B7)&"*")} -> 0 | H7: {=COUNTIFS(Sheet1!$A:$A,H$1,Sheet1!$D:$D,_xlfn.SWITCH($B7,"廣島","広島","鹿兒島","鹿児島","沖繩","沖縄","崎玉","埼玉","靜岡","静岡","櫪木","栃木","德島","徳島",$B7)&"*")} -> 0 | I7: {=COUNTIFS(Sheet1!$A:$A,I$1,Sheet1!$D:$D,_xlfn.SWITCH($B7,"廣島","広島","鹿兒島","鹿児島","沖繩","沖縄","崎玉","埼玉","靜岡","静岡","櫪木","栃木","德島","徳島",$B7)&"*")} -> 0 | J7: {=COUNTIFS(Sheet1!$A:$A,J$1,Sheet1!$D:$D,_xlfn.SWITCH($B7,"廣島","広島","鹿兒島","鹿児島","沖繩","沖縄","崎玉","埼玉","靜岡","静岡","櫪木","栃木","德島","徳島",$B7)&"*")} -> 0 | ... AH7: {=COUNTIFS(Sheet1!$A:$A,AH$1,Sheet1!$D:$D,_xlfn.SWITCH($B7,"廣島","広島","鹿兒島","鹿児島","沖繩","沖縄","崎玉","埼玉","靜岡","静岡","櫪木","栃木","德島","徳島",$B7)&"*")} -> 0
A8: county_7 | B8: 福岡 | C8: {=COUNTIFS(Sheet1!$A:$A,C$1,Sheet1!$D:$D,_xlfn.SWITCH($B8,"廣島","広島","鹿兒島","鹿児島","沖繩","沖縄","崎玉","埼玉","靜岡","静岡","櫪木","栃木","德島","徳島",$B8)&"*")} -> 5 | D8: {=COUNTIFS(Sheet1!$A:$A,D$1,Sheet1!$D:$D,_xlfn.SWITCH($B8,"廣島","広島","鹿兒島","鹿児島","沖繩","沖縄","崎玉","埼玉","靜岡","静岡","櫪木","栃木","德島","徳島",$B8)&"*")} -> 0 | E8: {=COUNTIFS(Sheet1!$A:$A,E$1,Sheet1!$D:$D,_xlfn.SWITCH($B8,"廣島","広島","鹿兒島","鹿児島","沖繩","沖縄","崎玉","埼玉","靜岡","静岡","櫪木","栃木","德島","徳島",$B8)&"*")} -> 2 | F8: {=COUNTIFS(Sheet1!$A:$A,F$1,Sheet1!$D:$D,_xlfn.SWITCH($B8,"廣島","広島","鹿兒島","鹿児島","沖繩","沖縄","崎玉","埼玉","靜岡","静岡","櫪木","栃木","德島","徳島",$B8)&"*")} -> 2 | G8: {=COUNTIFS(Sheet1!$A:$A,G$1,Sheet1!$D:$D,_xlfn.SWITCH($B8,"廣島","広島","鹿兒島","鹿児島","沖繩","沖縄","崎玉","埼玉","靜岡","静岡","櫪木","栃木","德島","徳島",$B8)&"*")} -> 4 | H8: {=COUNTIFS(Sheet1!$A:$A,H$1,Sheet1!$D:$D,_xlfn.SWITCH($B8,"廣島","広島","鹿兒島","鹿児島","沖繩","沖縄","崎玉","埼玉","靜岡","静岡","櫪木","栃木","德島","徳島",$B8)&"*")} -> 0 | I8: {=COUNTIFS(Sheet1!$A:$A,I$1,Sheet1!$D:$D,_xlfn.SWITCH($B8,"廣島","広島","鹿兒島","鹿児島","沖繩","沖縄","崎玉","埼玉","靜岡","静岡","櫪木","栃木","德島","徳島",$B8)&"*")} -> 4 | J8: {=COUNTIFS(Sheet1!$A:$A,J$1,Sheet1!$D:$D,_xlfn.SWITCH($B8,"廣島","広島","鹿兒島","鹿児島","沖繩","沖縄","崎玉","埼玉","靜岡","静岡","櫪木","栃木","德島","徳島",$B8)&"*")} -> 19 | ... AH8: {=COUNTIFS(Sheet1!$A:$A,AH$1,Sheet1!$D:$D,_xlfn.SWITCH($B8,"廣島","広島","鹿兒島","鹿児島","沖繩","沖縄","崎玉","埼玉","靜岡","静岡","櫪木","栃木","德島","徳島",$B8)&"*")} -> 9
A9: county_8 | B9: 福島 | C9: {=COUNTIFS(Sheet1!$A:$A,C$1,Sheet1!$D:$D,_xlfn.SWITCH($B9,"廣島","広島","鹿兒島","鹿児島","沖繩","沖縄","崎玉","埼玉","靜岡","静岡","櫪木","栃木","德島","徳島",$B9)&"*")} -> 0 | D9: {=COUNTIFS(Sheet1!$A:$A,D$1,Sheet1!$D:$D,_xlfn.SWITCH($B9,"廣島","広島","鹿兒島","鹿児島","沖繩","沖縄","崎玉","埼玉","靜岡","静岡","櫪木","栃木","德島","徳島",$B9)&"*")} -> 0 | E9: {=COUNTIFS(Sheet1!$A:$A,E$1,Sheet1!$D:$D,_xlfn.SWITCH($B9,"廣島","広島","鹿兒島","鹿児島","沖繩","沖縄","崎玉","埼玉","靜岡","静岡","櫪木","栃木","德島","徳島",$B9)&"*")} -> 0 | F9: {=COUNTIFS(Sheet1!$A:$A,F$1,Sheet1!$D:$D,_xlfn.SWITCH($B9,"廣島","広島","鹿兒島","鹿児島","沖繩","沖縄","崎玉","埼玉","靜岡","静岡","櫪木","栃木","德島","徳島",$B9)&"*")} -> 0 | G9: {=COUNTIFS(Sheet1!$A:$A,G$1,Sheet1!$D:$D,_xlfn.SWITCH($B9,"廣島","広島","鹿兒島","鹿児島","沖繩","沖縄","崎玉","埼玉","靜岡","静岡","櫪木","栃木","德島","徳島",$B9)&"*")} -> 0 | H9: {=COUNTIFS(Sheet1!$A:$A,H$1,Sheet1!$D:$D,_xlfn.SWITCH($B9,"廣島","広島","鹿兒島","鹿児島","沖繩","沖縄","崎玉","埼玉","靜岡","静岡","櫪木","栃木","德島","徳島",$B9)&"*")} -> 0 | I9: {=COUNTIFS(Sheet1!$A:$A,I$1,Sheet1!$D:$D,_xlfn.SWITCH($B9,"廣島","広島","鹿兒島","鹿児島","沖繩","沖縄","崎玉","埼玉","靜岡","静岡","櫪木","栃木","德島","徳島",$B9)&"*")} -> 0 | J9: {=COUNTIFS(Sheet1!$A:$A,J$1,Sheet1!$D:$D,_xlfn.SWITCH($B9,"廣島","広島","鹿兒島","鹿児島","沖繩","沖縄","崎玉","埼玉","靜岡","静岡","櫪木","栃木","德島","徳島",$B9)&"*")} -> 0 | ... AH9: {=COUNTIFS(Sheet1!$A:$A,AH$1,Sheet1!$D:$D,_xlfn.SWITCH($B9,"廣島","広島","鹿兒島","鹿児島","沖繩","沖縄","崎玉","埼玉","靜岡","静岡","櫪木","栃木","德島","徳島",$B9)&"*")} -> 0
A10: county_9 | B10: 岐阜 | C10: {=COUNTIFS(Sheet1!$A:$A,C$1,Sheet1!$D:$D,_xlfn.SWITCH($B10,"廣島","広島","鹿兒島","鹿児島","沖繩","沖縄","崎玉","埼玉","靜岡","静岡","櫪木","栃木","德島","徳島",$B10)&"*")} -> 0 | D10: {=COUNTIFS(Sheet1!$A:$A,D$1,Sheet1!$D:$D,_xlfn.SWITCH($B10,"廣島","広島","鹿兒島","鹿児島","沖繩","沖縄","崎玉","埼玉","靜岡","静岡","櫪木","栃木","德島","徳島",$B10)&"*")} -> 0 | E10: {=COUNTIFS(Sheet1!$A:$A,E$1,Sheet1!$D:$D,_xlfn.SWITCH($B10,"廣島","広島","鹿兒島","鹿児島","沖繩","沖縄","崎玉","埼玉","靜岡","静岡","櫪木","栃木","德島","徳島",$B10)&"*")} -> 1 | F10: {=COUNTIFS(Sheet1!$A:$A,F$1,Sheet1!$D:$D,_xlfn.SWITCH($B10,"廣島","広島","鹿兒島","鹿児島","沖繩","沖縄","崎玉","埼玉","靜岡","静岡","櫪木","栃木","德島","徳島",$B10)&"*")} -> 10 | G10: {=COUNTIFS(Sheet1!$A:$A,G$1,Sheet1!$D:$D,_xlfn.SWITCH($B10,"廣島","広島","鹿兒島","鹿児島","沖繩","沖縄","崎玉","埼玉","靜岡","静岡","櫪木","栃木","德島","徳島",$B10)&"*")} -> 2 | H10: {=COUNTIFS(Sheet1!$A:$A,H$1,Sheet1!$D:$D,_xlfn.SWITCH($B10,"廣島","広島","鹿兒島","鹿児島","沖繩","沖縄","崎玉","埼玉","靜岡","静岡","櫪木","栃木","德島","徳島",$B10)&"*")} -> 0 | I10: {=COUNTIFS(Sheet1!$A:$A,I$1,Sheet1!$D:$D,_xlfn.SWITCH($B10,"廣島","広島","鹿兒島","鹿児島","沖繩","沖縄","崎玉","埼玉","靜岡","静岡","櫪木","栃木","德島","徳島",$B10)&"*")} -> 6 | J10: {=COUNTIFS(Sheet1!$A:$A,J$1,Sheet1!$D:$D,_xlfn.SWITCH($B10,"廣島","広島","鹿兒島","鹿児島","沖繩","沖縄","崎玉","埼玉","靜岡","静岡","櫪木","栃木","德島","徳島",$B10)&"*")} -> 0 | ... AH10: {=COUNTIFS(Sheet1!$A:$A,AH$1,Sheet1!$D:$D,_xlfn.SWITCH($B10,"廣島","広島","鹿兒島","鹿児島","沖繩","沖縄","崎玉","埼玉","靜岡","静岡","櫪木","栃木","德島","徳島",$B10)&"*")} -> 0
A11: county_10 | B11: 群馬 | C11: {=COUNTIFS(Sheet1!$A:$A,C$1,Sheet1!$D:$D,_xlfn.SWITCH($B11,"廣島","広島","鹿兒島","鹿児島","沖繩","沖縄","崎玉","埼玉","靜岡","静岡","櫪木","栃木","德島","徳島",$B11)&"*")} -> 0 | D11: {=COUNTIFS(Sheet1!$A:$A,D$1,Sheet1!$D:$D,_xlfn.SWITCH($B11,"廣島","広島","鹿兒島","鹿児島","沖繩","沖縄","崎玉","埼玉","靜岡","静岡","櫪木","栃木","德島","徳島",$B11)&"*")} -> 0 | E11: {=COUNTIFS(Sheet1!$A:$A,E$1,Sheet1!$D:$D,_xlfn.SWITCH($B11,"廣島","広島","鹿兒島","鹿児島","沖繩","沖縄","崎玉","埼玉","靜岡","静岡","櫪木","栃木","德島","徳島",$B11)&"*")} -> 0 | F11: {=COUNTIFS(Sheet1!$A:$A,F$1,Sheet1!$D:$D,_xlfn.SWITCH($B11,"廣島","広島","鹿兒島","鹿児島","沖繩","沖縄","崎玉","埼玉","靜岡","静岡","櫪木","栃木","德島","徳島",$B11)&"*")} -> 0 | G11: {=COUNTIFS(Sheet1!$A:$A,G$1,Sheet1!$D:$D,_xlfn.SWITCH($B11,"廣島","広島","鹿兒島","鹿児島","沖繩","沖縄","崎玉","埼玉","靜岡","静岡","櫪木","栃木","德島","徳島",$B11)&"*")} -> 0 | H11: {=COUNTIFS(Sheet1!$A:$A,H$1,Sheet1!$D:$D,_xlfn.SWITCH($B11,"廣島","広島","鹿兒島","鹿児島","沖繩","沖縄","崎玉","埼玉","靜岡","静岡","櫪木","栃木","德島","徳島",$B11)&"*")} -> 0 | I11: {=COUNTIFS(Sheet1!$A:$A,I$1,Sheet1!$D:$D,_xlfn.SWITCH($B11,"廣島","広島","鹿兒島","鹿児島","沖繩","沖縄","崎玉","埼玉","靜岡","静岡","櫪木","栃木","德島","徳島",$B11)&"*")} -> 0 | J11: {=COUNTIFS(Sheet1!$A:$A,J$1,Sheet1!$D:$D,_xlfn.SWITCH($B11,"廣島","広島","鹿兒島","鹿児島","沖繩","沖縄","崎玉","埼玉","靜岡","静岡","櫪木","栃木","德島","徳島",$B11)&"*")} -> 0 | ... AH11: {=COUNTIFS(Sheet1!$A:$A,AH$1,Sheet1!$D:$D,_xlfn.SWITCH($B11,"廣島","広島","鹿兒島","鹿児島","沖繩","沖縄","崎玉","埼玉","靜岡","静岡","櫪木","栃木","德島","徳島",$B11)&"*")} -> 0
A12: county_11 | B12: 兵庫 | C12: {=COUNTIFS(Sheet1!$A:$A,C$1,Sheet1!$D:$D,_xlfn.SWITCH($B12,"廣島","広島","鹿兒島","鹿児島","沖繩","沖縄","崎玉","埼玉","靜岡","静岡","櫪木","栃木","德島","徳島",$B12)&"*")} -> 0 | D12: {=COUNTIFS(Sheet1!$A:$A,D$1,Sheet1!$D:$D,_xlfn.SWITCH($B12,"廣島","広島","鹿兒島","鹿児島","沖繩","沖縄","崎玉","埼玉","靜岡","静岡","櫪木","栃木","德島","徳島",$B12)&"*")} -> 1 | E12: {=COUNTIFS(Sheet1!$A:$A,E$1,Sheet1!$D:$D,_xlfn.SWITCH($B12,"廣島","広島","鹿兒島","鹿児島","沖繩","沖縄","崎玉","埼玉","靜岡","静岡","櫪木","栃木","德島","徳島",$B12)&"*")} -> 16 | F12: {=COUNTIFS(Sheet1!$A:$A,F$1,Sheet1!$D:$D,_xlfn.SWITCH($B12,"廣島","広島","鹿兒島","鹿児島","沖繩","沖縄","崎玉","埼玉","靜岡","静岡","櫪木","栃木","德島","徳島",$B12)&"*")} -> 6 | G12: {=COUNTIFS(Sheet1!$A:$A,G$1,Sheet1!$D:$D,_xlfn.SWITCH($B12,"廣島","広島","鹿兒島","鹿児島","沖繩","沖縄","崎玉","埼玉","靜岡","静岡","櫪木","栃木","德島","徳島",$B12)&"*")} -> 2 | H12: {=COUNTIFS(Sheet1!$A:$A,H$1,Sheet1!$D:$D,_xlfn.SWITCH($B12,"廣島","広島","鹿兒島","鹿児島","沖繩","沖縄","崎玉","埼玉","靜岡","静岡","櫪木","栃木","德島","徳島",$B12)&"*")} -> 0 | I12: {=COUNTIFS(Sheet1!$A:$A,I$1,Sheet1!$D:$D,_xlfn.SWITCH($B12,"廣島","広島","鹿兒島","鹿児島","沖繩","沖縄","崎玉","埼玉","靜岡","静岡","櫪木","栃木","德島","徳島",$B12)&"*")} -> 0 | J12: {=COUNTIFS(Sheet1!$A:$A,J$1,Sheet1!$D:$D,_xlfn.SWITCH($B12,"廣島","広島","鹿兒島","鹿児島","沖繩","沖縄","崎玉","埼玉","靜岡","静岡","櫪木","栃木","德島","徳島",$B12)&"*")} -> 19 | ... AH12: {=COUNTIFS(Sheet1!$A:$A,AH$1,Sheet1!$D:$D,_xlfn.SWITCH($B12,"廣島","広島","鹿兒島","鹿児島","沖繩","沖縄","崎玉","埼玉","靜岡","静岡","櫪木","栃木","德島","徳島",$B12)&"*")} -> 0
A13: county_12 | B13: 北海道 | C13: {=COUNTIFS(Sheet1!$A:$A,C$1,Sheet1!$D:$D,_xlfn.SWITCH($B13,"廣島","広島","鹿兒島","鹿児島","沖繩","沖縄","崎玉","埼玉","靜岡","静岡","櫪木","栃木","德島","徳島",$B13)&"*")} -> 0 | D13: {=COUNTIFS(Sheet1!$A:$A,D$1,Sheet1!$D:$D,_xlfn.SWITCH($B13,"廣島","広島","鹿兒島","鹿児島","沖繩","沖縄","崎玉","埼玉","靜岡","静岡","櫪木","栃木","德島","徳島",$B13)&"*")} -> 4 | E13: {=COUNTIFS(Sheet1!$A:$A,E$1,Sheet1!$D:$D,_xlfn.SWITCH($B13,"廣島","広島","鹿兒島","鹿児島","沖繩","沖縄","崎玉","埼玉","靜岡","静岡","櫪木","栃木","德島","徳島",$B13)&"*")} -> 0 | F13: {=COUNTIFS(Sheet1!$A:$A,F$1,Sheet1!$D:$D,_xlfn.SWITCH($B13,"廣島","広島","鹿兒島","鹿児島","沖繩","沖縄","崎玉","埼玉","靜岡","静岡","櫪木","栃木","德島","徳島",$B13)&"*")} -> 0 | G13: {=COUNTIFS(Sheet1!$A:$A,G$1,Sheet1!$D:$D,_xlfn.SWITCH($B13,"廣島","広島","鹿兒島","鹿児島","沖繩","沖縄","崎玉","埼玉","靜岡","静岡","櫪木","栃木","德島","徳島",$B13)&"*")} -> 0 | H13: {=COUNTIFS(Sheet1!$A:$A,H$1,Sheet1!$D:$D,_xlfn.SWITCH($B13,"廣島","広島","鹿兒島","鹿児島","沖繩","沖縄","崎玉","埼玉","靜岡","静岡","櫪木","栃木","德島","徳島",$B13)&"*")} -> 0 | I13: {=COUNTIFS(Sheet1!$A:$A,I$1,Sheet1!$D:$D,_xlfn.SWITCH($B13,"廣島","広島","鹿兒島","鹿児島","沖繩","沖縄","崎玉","埼玉","靜岡","静岡","櫪木","栃木","德島","徳島",$B13)&"*")} -> 23 | J13: {=COUNTIFS(Sheet1!$A:$A,J$1,Sheet1!$D:$D,_xlfn.SWITCH($B13,"廣島","広島","鹿兒島","鹿児島","沖繩","沖縄","崎玉","埼玉","靜岡","静岡","櫪木","栃木","德島","徳島",$B13)&"*")} -> 12 | ... AH13: {=COUNTIFS(Sheet1!$A:$A,AH$1,Sheet1!$D:$D,_xlfn.SWITCH($B13,"廣島","広島","鹿兒島","鹿児島","沖繩","沖縄","崎玉","埼玉","靜岡","静岡","櫪木","栃木","德島","徳島",$B13)&"*")} -> 0
... A48: county_47 | B48: 山形 | C48: {=COUNTIFS(Sheet1!$A:$A,C$1,Sheet1!$D:$D,_xlfn.SWITCH($B48,"廣島","広島","鹿兒島","鹿児島","沖繩","沖縄","崎玉","埼玉","靜岡","静岡","櫪木","栃木","德島","徳島",$B48)&"*")} -> 0 | D48: {=COUNTIFS(Sheet1!$A:$A,D$1,Sheet1!$D:$D,_xlfn.SWITCH($B48,"廣島","広島","鹿兒島","鹿児島","沖繩","沖縄","崎玉","埼玉","靜岡","静岡","櫪木","栃木","德島","徳島",$B48)&"*")} -> 0 | E48: {=COUNTIFS(Sheet1!$A:$A,E$1,Sheet1!$D:$D,_xlfn.SWITCH($B48,"廣島","広島","鹿兒島","鹿児島","沖繩","沖縄","崎玉","埼玉","靜岡","静岡","櫪木","栃木","德島","徳島",$B48)&"*")} -> 0 | F48: {=COUNTIFS(Sheet1!$A:$A,F$1,Sheet1!$D:$D,_xlfn.SWITCH($B48,"廣島","広島","鹿兒島","鹿児島","沖繩","沖縄","崎玉","埼玉","靜岡","静岡","櫪木","栃木","德島","徳島",$B48)&"*")} -> 0 | G48: {=COUNTIFS(Sheet1!$A:$A,G$1,Sheet1!$D:$D,_xlfn.SWITCH($B48,"廣島","広島","鹿兒島","鹿児島","沖繩","沖縄","崎玉","埼玉","靜岡","静岡","櫪木","栃木","德島","徳島",$B48)&"*")} -> 0 | H48: {=COUNTIFS(Sheet1!$A:$A,H$1,Sheet1!$D:$D,_xlfn.SWITCH($B48,"廣島","広島","鹿兒島","鹿児島","沖繩","沖縄","崎玉","埼玉","靜岡","静岡","櫪木","栃木","德島","徳島",$B48)&"*")} -> 1 | I48: {=COUNTIFS(Sheet1!$A:$A,I$1,Sheet1!$D:$D,_xlfn.SWITCH($B48,"廣島","広島","鹿兒島","鹿児島","沖繩","沖縄","崎玉","埼玉","靜岡","静岡","櫪木","栃木","德島","徳島",$B48)&"*")} -> 0 | J48: {=COUNTIFS(Sheet1!$A:$A,J$1,Sheet1!$D:$D,_xlfn.SWITCH($B48,"廣島","広島","鹿兒島","鹿児島","沖繩","沖縄","崎玉","埼玉","靜岡","静岡","櫪木","栃木","德島","徳島",$B48)&"*")} -> 0 | ... AH48: {=COUNTIFS(Sheet1!$A:$A,AH$1,Sheet1!$D:$D,_xlfn.SWITCH($B48,"廣島","広島","鹿兒島","鹿児島","沖繩","沖縄","崎玉","埼玉","靜岡","静岡","櫪木","栃木","德島","徳島",$B48)&"*")} -> 0
A49: 去過縣市數量 | C49: =COUNTIF(C$2:C$48,">0") -> 12 | D49: =COUNTIF(D$2:D$48,">0") -> 12 | E49: =COUNTIF(E$2:E$48,">0") -> 11 | F49: =COUNTIF(F$2:F$48,">0") -> 17 | G49: =COUNTIF(G$2:G$48,">0") -> 20 | H49: =COUNTIF(H$2:H$48,">0") -> 9 | I49: =COUNTIF(I$2:I$48,">0") -> 15 | J49: =COUNTIF(J$2:J$48,">0") -> 13 | ... AH49: =COUNTIF(AH$2:AH$48,">0") -> 6
